DEBUG Login function request received
DEBUG CustomTokenRefreshView request received
DEBUG Login function request received
DEBUG CustomTokenRefreshView request received
INFO Watching for file changes with StatReloader
DEBUG Login function request received
DEBUG CustomTokenRefreshView request received
INFO [mHTTP OPTIONS /auth/api/renew-access/ 200 [0.06, 172.28.0.1:60582][0m
INFO [mHTTP OPTIONS /auth/api/renew-access/ 200 [0.07, 172.28.0.1:60584][0m
DEBUG Allowing refresh token request in allowRefreshToken
DEBUG Allowing refresh token request in allowRefreshToken
DEBUG Refresh token in CustomTokenRefreshView: None
DEBUG Refresh token in CustomTokenRefreshView: None
WARNING Bad Request: /auth/api/renew-access/
WARNING [31;1mHTTP POST /auth/api/renew-access/ 400 [0.04, 172.28.0.1:60586][0m
WARNING Bad Request: /auth/api/renew-access/
WARNING [31;1mHTTP POST /auth/api/renew-access/ 400 [0.04, 172.28.0.1:60588][0m
INFO [mHTTP OPTIONS /auth/api/logout/ 200 [0.01, 172.28.0.1:60582][0m
INFO [mHTTP OPTIONS /auth/api/logout/ 200 [0.03, 172.28.0.1:60584][0m
DEBUG Logout request received for user: AnonymousUser
DEBUG Logout request received for user: AnonymousUser
DEBUG Refresh token found in cookies: None
DEBUG Refresh token found in cookies: None
ERROR Internal Server Error: /auth/api/logout/
Traceback (most recent call last):
  File "/usr/local/lib/python3.10/site-packages/asgiref/sync.py", line 518, in thread_handler
    raise exc_info[1]
  File "/usr/local/lib/python3.10/site-packages/django/core/handlers/exception.py", line 42, in inner
    response = await get_response(request)
  File "/usr/local/lib/python3.10/site-packages/django/core/handlers/base.py", line 253, in _get_response_async
    response = await wrapped_callback(
  File "/usr/local/lib/python3.10/site-packages/asgiref/sync.py", line 468, in __call__
    ret = await asyncio.shield(exec_coro)
  File "/usr/local/lib/python3.10/concurrent/futures/thread.py", line 58, in run
    result = self.fn(*self.args, **self.kwargs)
  File "/usr/local/lib/python3.10/site-packages/asgiref/sync.py", line 522, in thread_handler
    return func(*args, **kwargs)
  File "/usr/local/lib/python3.10/site-packages/django/views/decorators/csrf.py", line 65, in _view_wrapper
    return view_func(request, *args, **kwargs)
  File "/usr/local/lib/python3.10/site-packages/django/views/generic/base.py", line 104, in view
    return self.dispatch(request, *args, **kwargs)
  File "/usr/local/lib/python3.10/site-packages/rest_framework/views.py", line 509, in dispatch
    response = self.handle_exception(exc)
  File "/usr/local/lib/python3.10/site-packages/rest_framework/views.py", line 469, in handle_exception
    self.raise_uncaught_exception(exc)
  File "/usr/local/lib/python3.10/site-packages/rest_framework/views.py", line 480, in raise_uncaught_exception
    raise exc
  File "/usr/local/lib/python3.10/site-packages/rest_framework/views.py", line 506, in dispatch
    response = handler(request, *args, **kwargs)
  File "/app/Django_backend_project/auth_app/views.py", line 167, in post
    elif user.username:
UnboundLocalError: local variable 'user' referenced before assignment
ERROR Internal Server Error: /auth/api/logout/
Traceback (most recent call last):
  File "/usr/local/lib/python3.10/site-packages/asgiref/sync.py", line 518, in thread_handler
    raise exc_info[1]
  File "/usr/local/lib/python3.10/site-packages/django/core/handlers/exception.py", line 42, in inner
    response = await get_response(request)
  File "/usr/local/lib/python3.10/site-packages/django/core/handlers/base.py", line 253, in _get_response_async
    response = await wrapped_callback(
  File "/usr/local/lib/python3.10/site-packages/asgiref/sync.py", line 468, in __call__
    ret = await asyncio.shield(exec_coro)
  File "/usr/local/lib/python3.10/concurrent/futures/thread.py", line 58, in run
    result = self.fn(*self.args, **self.kwargs)
  File "/usr/local/lib/python3.10/site-packages/asgiref/sync.py", line 522, in thread_handler
    return func(*args, **kwargs)
  File "/usr/local/lib/python3.10/site-packages/django/views/decorators/csrf.py", line 65, in _view_wrapper
    return view_func(request, *args, **kwargs)
  File "/usr/local/lib/python3.10/site-packages/django/views/generic/base.py", line 104, in view
    return self.dispatch(request, *args, **kwargs)
  File "/usr/local/lib/python3.10/site-packages/rest_framework/views.py", line 509, in dispatch
    response = self.handle_exception(exc)
  File "/usr/local/lib/python3.10/site-packages/rest_framework/views.py", line 469, in handle_exception
    self.raise_uncaught_exception(exc)
  File "/usr/local/lib/python3.10/site-packages/rest_framework/views.py", line 480, in raise_uncaught_exception
    raise exc
  File "/usr/local/lib/python3.10/site-packages/rest_framework/views.py", line 506, in dispatch
    response = handler(request, *args, **kwargs)
  File "/app/Django_backend_project/auth_app/views.py", line 167, in post
    elif user.username:
UnboundLocalError: local variable 'user' referenced before assignment
ERROR [35;1mHTTP POST /auth/api/logout/ 500 [0.10, 172.28.0.1:60588][0m
ERROR [35;1mHTTP POST /auth/api/logout/ 500 [0.16, 172.28.0.1:60586][0m
